<?xml version="1.0" encoding="utf-8"?>
<!-- This URDF was automatically created by SolidWorks to URDF Exporter! Originally created by Stephen Brawner (brawner@gmail.com) 
     Commit Version: 1.6.0-4-g7f85cfe  Build Version: 1.6.7995.38578
     For more information, please see http://wiki.ros.org/sw_urdf_exporter -->
<robot
  name="arm_urdf">
  <link
    name="Link_1">
    <inertial>
      <origin
        xyz="0.0062234 -0.0091682 -0.053285"
        rpy="0 0 0" />
      <mass
        value="3.331" />
      <inertia
        ixx="0.010182"
        ixy="-1.9873E-07"
        ixz="-8.6627E-05"
        iyy="0.0035887"
        iyz="-2.3959E-06"
        izz="0.0094953" />
    </inertial>
    <visual>
      <origin
        xyz="0 0 0"
        rpy="0 0 0" />
      <geometry>
        <mesh
          filename="package://arm_urdf/meshes/visual/Link_1.STL" />
      </geometry>
      <material
        name="">
        <color
          rgba="0.75294 0.75294 0.75294 1" />
      </material>
    </visual>
    <collision>
      <origin
        xyz="0 0 0"
        rpy="0 0 0" />
      <geometry>
        <mesh
          filename="package://arm_urdf/meshes/visual/Link_1.STL" />
      </geometry>
    </collision>
  </link>
  <link
    name="Link_2">
    <inertial>
      <origin
        xyz="0.060972 -1.3672E-05 0.064758"
        rpy="0 0 0" />
      <mass
        value="0.51625" />
      <inertia
        ixx="0.00061348"
        ixy="5.84E-19"
        ixz="-0.00027551"
        iyy="0.0023924"
        iyz="5.7914E-20"
        izz="0.0021849" />
    </inertial>
    <visual>
      <origin
        xyz="0 0 0"
        rpy="0 0 0" />
      <geometry>
        <mesh
          filename="package://arm_urdf/meshes/visual/Link_2.STL" />
      </geometry>
      <material
        name="">
        <color
          rgba="0.75294 0.75294 0.75294 1" />
      </material>
    </visual>
    <collision>
      <origin
        xyz="0 0 0"
        rpy="0 0 0" />
      <geometry>
        <mesh
          filename="package://arm_urdf/meshes/visual/Link_2.STL" />
      </geometry>
    </collision>
  </link>
  <joint
    name="Joint_1"
    type="revolute">
    <origin
      xyz="0 0 0.0207625000000001"
      rpy="0 0 0" />
    <parent
      link="Link_1" />
    <child
      link="Link_2" />
    <axis
      xyz="0 0 1" />
    <limit effort="100.0" velocity="1.0" lower="-1.57" upper="1.57"/>
  </joint>
  <link
    name="Link_3">
    <inertial>
      <origin
        xyz="0.24805 -2.9219E-06 0.26596"
        rpy="0 0 0" />
      <mass
        value="1.9352" />
      <inertia
        ixx="0.038214"
        ixy="-9.3768E-16"
        ixz="-0.045119"
        iyy="0.099274"
        iyz="-7.467E-16"
        izz="0.061195" />
    </inertial>
    <visual>
      <origin
        xyz="0 0 0"
        rpy="0 0 0" />
      <geometry>
        <mesh
          filename="package://arm_urdf/meshes/visual/Link_3.STL" />
      </geometry>
      <material
        name="">
        <color
          rgba="0.75294 0.75294 0.75294 1" />
      </material>
    </visual>
    <collision>
      <origin
        xyz="0 0 0"
        rpy="0 0 0" />
      <geometry>
        <mesh
          filename="package://arm_urdf/meshes/visual/Link_3.STL" />
      </geometry>
    </collision>
  </link>
  <joint
    name="Joint_2"
    type="revolute">
    <origin
      xyz="0 0 0.1"
      rpy="0 0 0" />
    <parent
      link="Link_2" />
    <child
      link="Link_3" />
    <axis
      xyz="0 -1 0" />
    <limit effort="100.0" velocity="0.0234" lower="-0.3858" upper="0.4626"/>
  </joint>
  <link
    name="Link_4">
    <inertial>
      <origin
        xyz="-0.019735 -0.00015211 0.017938"
        rpy="0 0 0" />
      <mass
        value="0.90456" />
      <inertia
        ixx="0.00076075"
        ixy="-9.2563E-07"
        ixz="0.00067479"
        iyy="0.0019193"
        iyz="5.3407E-07"
        izz="0.001539" />
    </inertial>
    <visual>
      <origin
        xyz="0 0 0"
        rpy="0 0 0" />
      <geometry>
        <mesh
          filename="package://arm_urdf/meshes/visual/Link_4.STL" />
      </geometry>
      <material
        name="">
        <color
          rgba="0.75294 0.75294 0.75294 1" />
      </material>
    </visual>
    <collision>
      <origin
        xyz="0 0 0"
        rpy="0 0 0" />
      <geometry>
        <mesh
          filename="package://arm_urdf/meshes/visual/Link_4.STL" />
      </geometry>
    </collision>
  </link>
  <joint
    name="Joint_3"
    type="revolute">
    <origin
      xyz="0.558012701892218 0 0.466506350946108"
      rpy="0 0 0" />
    <parent
      link="Link_3" />
    <child
      link="Link_4" />
    <axis
      xyz="0 -1 0" />
    <limit effort="100.0" velocity="0.03688" lower="-0.6578" upper="0.3033"/>
  </joint>
  <link
    name="Link_5">
    <inertial>
      <origin
        xyz="0.54652 0.0045965 -0.31553"
        rpy="0 0 0" />
      <mass
        value="1.42" />
      <inertia
        ixx="0.0027553"
        ixy="6.9116E-08"
        ixz="0.0039305"
        iyy="0.0098338"
        iyz="-1.1945E-08"
        izz="0.0072934" />
    </inertial>
    <visual>
      <origin
        xyz="0 0 0"
        rpy="0 0 0" />
      <geometry>
        <mesh
          filename="package://arm_urdf/meshes/visual/Link_5.STL" />
      </geometry>
      <material
        name="">
        <color
          rgba="0.75294 0.75294 0.75294 1" />
      </material>
    </visual>
    <collision>
      <origin
        xyz="0 0 0"
        rpy="0 0 0" />
      <geometry>
        <mesh
          filename="package://arm_urdf/meshes/visual/Link_5.STL" />
      </geometry>
    </collision>
  </link>
  <joint
    name="Joint_4"
    type="revolute">
    <origin
      xyz="-0.0209336725054375 -0.000155363339502348 0.0120860614561421"
      rpy="0 0 0" />
    <parent
      link="Link_4" />
    <child
      link="Link_5" />
    <axis
      xyz="-0.866025403784437 0 0.500000000000002" />
    <limit effort="100.0" velocity="0.60385" lower="-3.14" upper="3.14"/>
  </joint>
  <link
    name="Link_6">
    <inertial>
      <origin
        xyz="0.032376 -0.032402 0.0074594"
        rpy="0 0 0" />
      <mass
        value="0.4426" />
      <inertia
        ixx="0.00027024"
        ixy="1.7939E-08"
        ixz="6.3524E-08"
        iyy="0.0001854"
        iyz="1.167E-06"
        izz="0.00015749" />
    </inertial>
    <visual>
      <origin
        xyz="0 0 0"
        rpy="0 0 0" />
      <geometry>
        <mesh
          filename="package://arm_urdf/meshes/visual/Link_6.STL" />
      </geometry>
      <material
        name="">
        <color
          rgba="0.75294 0.75294 0.75294 1" />
      </material>
    </visual>
    <collision>
      <origin
        xyz="0 0 0"
        rpy="0 0 0" />
      <geometry>
        <mesh
          filename="package://arm_urdf/meshes/visual/Link_6.STL" />
      </geometry>
    </collision>
  </link>
  <joint
    name="Joint_5"
    type="revolute">
    <origin
      xyz="0.63745932252309 0 -0.368037311456142"
      rpy="0 0 0" />
    <parent
      link="Link_5" />
    <child
      link="Link_6" />
    <axis
      xyz="0 -1 0" />
    <limit effort="100.0" velocity="0.0415" lower="-2.0944" upper="1.0472"/>
  </joint>
  <link
    name="Link_7">
    <inertial>
      <origin
        xyz="0.087198 -1.9706E-15 8.8818E-16"
        rpy="0 0 0" />
      <mass
        value="1.4764" />
      <inertia
        ixx="0.0058401"
        ixy="-1.3237E-19"
        ixz="1.929E-19"
        iyy="0.0043142"
        iyz="-4.4544E-21"
        izz="0.0097785" />
    </inertial>
    <visual>
      <origin
        xyz="0 0 0"
        rpy="0 0 0" />
      <geometry>
        <mesh
          filename="package://arm_urdf/meshes/visual/Link_7.STL" />
      </geometry>
      <material
        name="">
        <color
          rgba="0.79216 0.81961 0.93333 1" />
      </material>
    </visual>
    <collision>
      <origin
        xyz="0 0 0"
        rpy="0 0 0" />
      <geometry>
        <mesh
          filename="package://arm_urdf/meshes/visual/Link_7.STL" />
      </geometry>
    </collision>
  </link>
  <joint
    name="Joint_6"
    type="revolute">
    <origin
      xyz="0.0621500000000025 -0.0285875000000056 0"
      rpy="0 0 0" />
    <parent
      link="Link_6" />
    <child
      link="Link_7" />
    <axis
      xyz="-1 0 0" />
    <limit effort="100.0" velocity="0.28545" lower="-3.14" upper="3.14"/>
  </joint>
</robot>
