<?xml version="1.0" encoding="utf-8"?>
<!-- This URDF was automatically created by SolidWorks to URDF Exporter! Originally created by Stephen Brawner (brawner@gmail.com) 
     Commit Version: 1.6.0-4-g7f85cfe  Build Version: 1.6.7995.38578
     For more information, please see http://wiki.ros.org/sw_urdf_exporter -->
<robot
  name="arm_urdf">
  <link
    name="Link_1">
    <inertial>
      <origin
        xyz="0.00622341511954164 -0.00916820792441791 -0.0469349641137912"
        rpy="0 0 0" />
      <mass
        value="3.33097898163857" />
      <inertia
        ixx="0.0101819650222787"
        ixy="-1.98734712904888E-07"
        ixz="-8.66271809934504E-05"
        iyy="0.00358872310944578"
        iyz="-2.39587965010669E-06"
        izz="0.00949532820710057" />
    </inertial>
    <visual>
      <origin
        xyz="0 0 0"
        rpy="0 0 0" />
      <geometry>
        <mesh
          filename="package://arm_urdf/meshes/visual/Link_1.STL" />
      </geometry>
      <material
        name="">
        <color
          rgba="0.752941176470588 0.752941176470588 0.752941176470588 1" />
      </material>
    </visual>
    <collision>
      <origin
        xyz="0 0 0"
        rpy="0 0 0" />
      <geometry>
        <mesh
          filename="package://arm_urdf/meshes/collision/Link_1.STL" />
      </geometry>
    </collision>
  </link>
  <link
    name="Link_2">
    <inertial>
      <origin
        xyz="0.060972336777117 -1.36723296035798E-05 0.0647576977642935"
        rpy="0 0 0" />
      <mass
        value="0.516253747755485" />
      <inertia
        ixx="0.000613480594305293"
        ixy="5.38160003974242E-19"
        ixz="-0.000275510697436789"
        iyy="0.0023924326610652"
        iyz="2.3245534780382E-20"
        izz="0.00218490294968333" />
    </inertial>
    <visual>
      <origin
        xyz="0 0 0"
        rpy="0 0 0" />
      <geometry>
        <mesh
          filename="package://arm_urdf/meshes/visual/Link_2.STL" />
      </geometry>
      <material
        name="">
        <color
          rgba="0.752941176470588 0.752941176470588 0.752941176470588 1" />
      </material>
    </visual>
    <collision>
      <origin
        xyz="0 0 0"
        rpy="0 0 0" />
      <geometry>
        <mesh
          filename="package://arm_urdf/meshes/collision/Link_2.STL" />
      </geometry>
    </collision>
  </link>
  <joint
    name="Joint_1"
    type="continuous">
    <origin
      xyz="0 0 0.027113"
      rpy="0 0 0" />
    <parent
      link="Link_1" />
    <child
      link="Link_2" />
    <axis
      xyz="0 0 1" />
  </joint>
  <link
    name="Link_3">
    <inertial>
      <origin
        xyz="0.248052997344685 -2.92185847471094E-06 0.265955531896042"
        rpy="0 0 0" />
      <mass
        value="1.93524935633317" />
      <inertia
        ixx="0.0382135022216721"
        ixy="-4.49867345730304E-16"
        ixz="-0.0451188810097449"
        iyy="0.099274210856537"
        iyz="-3.34175860324251E-16"
        izz="0.0611945626947677" />
    </inertial>
    <visual>
      <origin
        xyz="0 0 0"
        rpy="0 0 0" />
      <geometry>
        <mesh
          filename="package://arm_urdf/meshes/visual/Link_3.STL" />
      </geometry>
      <material
        name="">
        <color
          rgba="0.752941176470588 0.752941176470588 0.752941176470588 1" />
      </material>
    </visual>
    <collision>
      <origin
        xyz="0 0 0"
        rpy="0 0 0" />
      <geometry>
        <mesh
          filename="package://arm_urdf/meshes/collision/Link_3.STL" />
      </geometry>
    </collision>
  </link>
  <joint
    name="Joint_2"
    type="continuous">
    <origin
      xyz="0 0 0.1"
      rpy="0 0 0" />
    <parent
      link="Link_2" />
    <child
      link="Link_3" />
    <axis
      xyz="0 -1 0" />
  </joint>
  <link
    name="Link_4">
    <inertial>
      <origin
        xyz="-0.0241622970765439 -0.000145725953688065 0.0139342486656481"
        rpy="0 0 0" />
      <mass
        value="0.798545293139664" />
      <inertia
        ixx="0.000725346582901255"
        ixy="-9.25632625871902E-07"
        ixz="0.000642244287450308"
        iyy="0.00182700177776413"
        iyz="5.34067929115977E-07"
        izz="0.00146510835419295" />
    </inertial>
    <visual>
      <origin
        xyz="0 0 0"
        rpy="0 0 0" />
      <geometry>
        <mesh
          filename="package://arm_urdf/meshes/visual/Link_4.STL" />
      </geometry>
      <material
        name="">
        <color
          rgba="0.752941176470588 0.752941176470588 0.752941176470588 1" />
      </material>
    </visual>
    <collision>
      <origin
        xyz="0 0 0"
        rpy="0 0 0" />
      <geometry>
        <mesh
          filename="package://arm_urdf/meshes/collision/Link_4.STL" />
      </geometry>
    </collision>
  </link>
  <joint
    name="Joint_3"
    type="continuous">
    <origin
      xyz="0.55801 0 0.46651"
      rpy="0 0 0" />
    <parent
      link="Link_3" />
    <child
      link="Link_4" />
    <axis
      xyz="0 -1 0" />
  </joint>
  <link
    name="Link_5">
    <inertial>
      <origin
        xyz="0.54652151239787 0.0045965233223425 -0.315526632247381"
        rpy="0 0 0" />
      <mass
        value="1.41995187784121" />
      <inertia
        ixx="0.00275531148319508"
        ixy="6.91162703332479E-08"
        ixz="0.00393052302354834"
        iyy="0.00983380816136502"
        iyz="-1.19451574736834E-08"
        izz="0.00729337097705166" />
    </inertial>
    <visual>
      <origin
        xyz="0 0 0"
        rpy="0 0 0" />
      <geometry>
        <mesh
          filename="package://arm_urdf/meshes/visual/Link_5.STL" />
      </geometry>
      <material
        name="">
        <color
          rgba="0.752941176470588 0.752941176470588 0.752941176470588 1" />
      </material>
    </visual>
    <collision>
      <origin
        xyz="0 0 0"
        rpy="0 0 0" />
      <geometry>
        <mesh
          filename="package://arm_urdf/meshes/collision/Link_5.STL" />
      </geometry>
    </collision>
  </link>
  <joint
    name="Joint_4"
    type="continuous">
    <origin
      xyz="-0.020934 -0.00015536 0.012086"
      rpy="0 0 0" />
    <parent
      link="Link_4" />
    <child
      link="Link_5" />
    <axis
      xyz="-0.86603 0 0.5" />
  </joint>
  <link
    name="Link_6">
    <inertial>
      <origin
        xyz="-0.00885742110815235 -0.0330787531924534 -0.0330128346122342"
        rpy="0 0 0" />
      <mass
        value="0.462055180258125" />
      <inertia
        ixx="0.000186526424548505"
        ixy="1.01051408727741E-06"
        ixz="4.85716237256025E-05"
        iyy="0.000186429229057267"
        iyz="-5.92211171029459E-07"
        izz="0.000242741841550989" />
    </inertial>
    <visual>
      <origin
        xyz="0 0 0"
        rpy="0 0 0" />
      <geometry>
        <mesh
          filename="package://arm_urdf/meshes/visual/Link_6.STL" />
      </geometry>
      <material
        name="">
        <color
          rgba="0.752941176470588 0.752941176470588 0.752941176470588 1" />
      </material>
    </visual>
    <collision>
      <origin
        xyz="0 0 0"
        rpy="0 0 0" />
      <geometry>
        <mesh
          filename="package://arm_urdf/meshes/collision/Link_6.STL" />
      </geometry>
    </collision>
  </link>
  <joint
    name="Joint_5"
    type="continuous">
    <origin
      xyz="0.63746 0 -0.36804"
      rpy="0 0 0" />
    <parent
      link="Link_5" />
    <child
      link="Link_6" />
    <axis
      xyz="0 -1 0" />
  </joint>
  <link
    name="Link_7">
    <inertial>
      <origin
        xyz="-0.0202239496006344 2.28289609438548E-15 -0.0350289082380117"
        rpy="0 0 0" />
      <mass
        value="1.47639025500324" />
      <inertia
        ixx="0.00879392218461711"
        ixy="1.12722455111749E-17"
        ixz="-0.00170541271279087"
        iyy="0.00431422034842634"
        iyz="-7.58974100183454E-18"
        izz="0.00682468120699871" />
    </inertial>
    <visual>
      <origin
        xyz="0 0 0"
        rpy="0 0 0" />
      <geometry>
        <mesh
          filename="package://arm_urdf/meshes/visual/Link_7.STL" />
      </geometry>
      <material
        name="">
        <color
          rgba="0.792156862745098 0.819607843137255 0.933333333333333 1" />
      </material>
    </visual>
    <collision>
      <origin
        xyz="0 0 0"
        rpy="0 0 0" />
      <geometry>
        <mesh
          filename="package://arm_urdf/meshes/collision/Link_7.STL" />
      </geometry>
    </collision>
  </link>
  <joint
    name="Joint_6"
    type="continuous">
    <origin
      xyz="-0.05445 -0.028588 -0.09431"
      rpy="0 0 0" />
    <parent
      link="Link_6" />
    <child
      link="Link_7" />
    <axis
      xyz="0.5 0 0.86603" />
  </joint>
</robot>
